Traceback (most recent call last):
  File "C:\Users\acer\AppData\Local\Programs\Python\Python312\Lib\site-packages\jupyter_cache\executors\utils.py", line 58, in single_nb_execution
    executenb(
  File "C:\Users\acer\AppData\Local\Programs\Python\Python312\Lib\site-packages\nbclient\client.py", line 1314, in execute
    return NotebookClient(nb=nb, resources=resources, km=km, **kwargs).execute()
           ^^^^^^^^^^^^^^^^^^^^^^^^^^^^^^^^^^^^^^^^^^^^^^^^^^^^^^^^^^^^^^^^^^^^^
  File "C:\Users\acer\AppData\Local\Programs\Python\Python312\Lib\site-packages\jupyter_core\utils\__init__.py", line 165, in wrapped
    return loop.run_until_complete(inner)
           ^^^^^^^^^^^^^^^^^^^^^^^^^^^^^^
  File "C:\Users\acer\AppData\Local\Programs\Python\Python312\Lib\asyncio\base_events.py", line 664, in run_until_complete
    return future.result()
           ^^^^^^^^^^^^^^^
  File "C:\Users\acer\AppData\Local\Programs\Python\Python312\Lib\site-packages\nbclient\client.py", line 709, in async_execute
    await self.async_execute_cell(
  File "C:\Users\acer\AppData\Local\Programs\Python\Python312\Lib\site-packages\nbclient\client.py", line 1062, in async_execute_cell
    await self._check_raise_for_error(cell, cell_index, exec_reply)
  File "C:\Users\acer\AppData\Local\Programs\Python\Python312\Lib\site-packages\nbclient\client.py", line 918, in _check_raise_for_error
    raise CellExecutionError.from_cell_and_msg(cell, exec_reply_content)
nbclient.exceptions.CellExecutionError: An error occurred while executing the following cell:
------------------
import mysql.connector
import pandas as pd

# koneksi ke mysql
conn = mysql.connector.connect(
    host = 'mohammadilhamyusronrisqi088-mohammadilhamyusronrisqi088.a.aivencloud.com',
    port = 14305,
    user = 'avnadmin',
    password = 'AVNS_WWfj_XdD5SWZ92zK8vz',
    database = 'defaultdb'
)

# kode sql untuk membaca data dengan panda
query = "SELECT * FROM iris"
dataset = pd.read_sql(query, conn)

# Menutup koneksi ke database
conn.close()
------------------


[1;31m---------------------------------------------------------------------------[0m
[1;31mModuleNotFoundError[0m                       Traceback (most recent call last)
Cell [1;32mIn[2], line 2[0m
[0;32m      1[0m [38;5;28;01mimport[39;00m [38;5;21;01mmysql[39;00m[38;5;21;01m.[39;00m[38;5;21;01mconnector[39;00m
[1;32m----> 2[0m [38;5;28;01mimport[39;00m [38;5;21;01mpandas[39;00m [38;5;28;01mas[39;00m [38;5;21;01mpd[39;00m
[0;32m      4[0m [38;5;66;03m# koneksi ke mysql[39;00m
[0;32m      5[0m conn [38;5;241m=[39m mysql[38;5;241m.[39mconnector[38;5;241m.[39mconnect(
[0;32m      6[0m     host [38;5;241m=[39m [38;5;124m'[39m[38;5;124mmohammadilhamyusronrisqi088-mohammadilhamyusronrisqi088.a.aivencloud.com[39m[38;5;124m'[39m,
[0;32m      7[0m     port [38;5;241m=[39m [38;5;241m14305[39m,
[1;32m   (...)[0m
[0;32m     10[0m     database [38;5;241m=[39m [38;5;124m'[39m[38;5;124mdefaultdb[39m[38;5;124m'[39m
[0;32m     11[0m )

[1;31mModuleNotFoundError[0m: No module named 'pandas'

